<?xml version="1.0" encoding="utf-8"?>
<!-- This URDF was automatically created by SolidWorks to URDF Exporter! Originally created by Stephen Brawner (brawner@gmail.com) 
     Commit Version: 1.6.0-1-g15f4949  Build Version: 1.6.7594.29634
     For more information, please see http://wiki.ros.org/sw_urdf_exporter -->
<robot
  name="descripe">
  <link
    name="base_link">
    <inertial>
      <origin
        xyz="-5.19355364633906E-05 2.96857670669115E-05 0.00561243921806476"
        rpy="0 0 0" />
      <mass
        value="1.52868437083991" />
      <inertia
        ixx="0.00427436516465699"
        ixy="-7.44281487802473E-07"
        ixz="1.301987734112E-07"
        iyy="0.00427684753161486"
        iyz="-1.57041596548467E-07"
        izz="0.00821958386021356" />
    </inertial>
    <visual>
      <origin
        xyz="0 0 0"
        rpy="0 0 0" />
      <geometry>
        <mesh
          filename="package://descripe/meshes/base_link.STL" />
      </geometry>
      <material
        name="">
        <color
          rgba="0.792156862745098 0.819607843137255 0.933333333333333 1" />
      </material>
    </visual>
    <collision>
      <origin
        xyz="0 0 0"
        rpy="0 0 0" />
      <geometry>
        <mesh
          filename="package://descripe/meshes/base_link.STL" />
      </geometry>
    </collision>
  </link>
  <link
    name="1">
    <inertial>
      <origin
        xyz="0.0361016048824093 -3.81998846166187E-08 -2.16627963900429E-08"
        rpy="0 0 0" />
      <mass
        value="0.017511882705247" />
      <inertia
        ixx="7.21182417832099E-07"
        ixy="-3.05683665432509E-11"
        ixz="-1.54396755567864E-11"
        iyy="1.08038679441715E-05"
        iyz="-4.4259405144789E-12"
        izz="1.12029329427599E-05" />
    </inertial>
    <visual>
      <origin
        xyz="0 0 0"
        rpy="0 0 0" />
      <geometry>
        <mesh
          filename="package://descripe/meshes/1.STL" />
      </geometry>
      <material
        name="">
        <color
          rgba="0.792156862745098 0.819607843137255 0.933333333333333 1" />
      </material>
    </visual>
    <collision>
      <origin
        xyz="0 0 0"
        rpy="0 0 0" />
      <geometry>
        <mesh
          filename="package://descripe/meshes/1.STL" />
      </geometry>
    </collision>
  </link>
  <joint
    name="1"
    type="revolute">
    <origin
      xyz="0.13 0 -0.02"
      rpy="1.5708 -0.08134 0" />
    <parent
      link="base_link" />
    <child
      link="1" />
    <axis
      xyz="0 0 -1" />
    <limit
      lower="0"
      upper="6.28"
      effort="1000"
      velocity="1000" />
  </joint>
  <link
    name="11">
    <inertial>
      <origin
        xyz="0.197424984552297 3.21550867238285E-05 0.00010130161816635"
        rpy="0 0 0" />
      <mass
        value="0.00971847027454767" />
      <inertia
        ixx="5.27630352845987E-08"
        ixy="-1.00662349903563E-13"
        ixz="2.55645061504699E-14"
        iyy="8.64526176409532E-05"
        iyz="1.01309643570161E-09"
        izz="8.64554877354837E-05" />
    </inertial>
    <visual>
      <origin
        xyz="0 0 0"
        rpy="0 0 0" />
      <geometry>
        <mesh
          filename="package://descripe/meshes/11.STL" />
      </geometry>
      <material
        name="">
        <color
          rgba="0.792156862745098 0.819607843137255 0.933333333333333 1" />
      </material>
    </visual>
    <collision>
      <origin
        xyz="0 0 0"
        rpy="0 0 0" />
      <geometry>
        <mesh
          filename="package://descripe/meshes/11.STL" />
      </geometry>
    </collision>
  </link>
  <joint
    name="11"
    type="revolute">
    <origin
      xyz="0.0800000000000004 0 0.0139999999999985"
      rpy="0 0 -2.14225469636022" />
    <parent
      link="1" />
    <child
      link="11" />
    <axis
      xyz="0 0 -1" />
    <limit
      lower="0"
      upper="6.28"
      effort="1000"
      velocity="1000" />
  </joint>
  <link
    name="111">
    <inertial>
      <origin
        xyz="-2.48412401759879E-15 7.42461647718073E-16 -0.00407409549700027"
        rpy="0 0 0" />
      <mass
        value="0.000539506193520435" />
      <inertia
        ixx="1.25867201372513E-08"
        ixy="3.10192729707385E-25"
        ixz="-5.77475465138582E-23"
        iyy="1.25867201372513E-08"
        iyz="-1.04121359605112E-22"
        izz="3.31683628481004E-09" />
    </inertial>
    <visual>
      <origin
        xyz="0 0 0"
        rpy="0 0 0" />
      <geometry>
        <mesh
          filename="package://descripe/meshes/111.STL" />
      </geometry>
      <material
        name="">
        <color
          rgba="0.505882352941176 0.505882352941176 0.584313725490196 1" />
      </material>
    </visual>
    <collision>
      <origin
        xyz="0 0 0"
        rpy="0 0 0" />
      <geometry>
        <mesh
          filename="package://descripe/meshes/111.STL" />
      </geometry>
    </collision>
  </link>
  <joint
    name="111"
    type="revolute">
    <origin
      xyz="0.394850000000003 0 0"
      rpy="0 0 0" />
    <parent
      link="11" />
    <child
      link="111" />
    <axis
      xyz="0 0 -1" />
    <limit
      lower="0"
      upper="6.28"
      effort="1000"
      velocity="1000" />
  </joint>
  <link
    name="end">
    <inertial>
      <origin
        xyz="-6.77813360994151E-12 4.78702383288621E-10 -7.20703600430445E-05"
        rpy="0 0 0" />
      <mass
        value="0.0073232288565885" />
      <inertia
        ixx="1.29389854254997E-06"
        ixy="5.90347232709036E-14"
        ixz="3.32239753383043E-16"
        iyy="1.29389851994944E-06"
        iyz="1.08771194613915E-15"
        izz="2.45573100523025E-06" />
    </inertial>
    <visual>
      <origin
        xyz="0 0 0"
        rpy="0 0 0" />
      <geometry>
        <mesh
          filename="package://descripe/meshes/end.STL" />
      </geometry>
      <material
        name="">
        <color
          rgba="0.792156862745098 0.819607843137255 0.933333333333333 1" />
      </material>
    </visual>
    <collision>
      <origin
        xyz="0 0 0"
        rpy="0 0 0" />
      <geometry>
        <mesh
          filename="package://descripe/meshes/end.STL" />
      </geometry>
    </collision>
  </link>
  <joint
    name="end"
    type="fixed">
    <origin
      xyz="0.011235 -0.021058 -0.014"
      rpy="-1.5708 0 2.0609" />
    <parent
      link="111" />
    <child
      link="end" />
    <axis
      xyz="0 0 0" />
  </joint>
  <link
    name="12">
    <inertial>
      <origin
        xyz="0.19742501544071 -3.21557342481474E-05 -0.000101301405876497"
        rpy="0 0 0" />
      <mass
        value="0.00971847007327643" />
      <inertia
        ixx="5.27630255465164E-08"
        ixy="-7.6472615104267E-14"
        ixz="1.79725486257925E-14"
        iyy="8.64526176495693E-05"
        iyz="1.01311232467429E-09"
        izz="8.64554877047388E-05" />
    </inertial>
    <visual>
      <origin
        xyz="0 0 0"
        rpy="0 0 0" />
      <geometry>
        <mesh
          filename="package://descripe/meshes/12.STL" />
      </geometry>
      <material
        name="">
        <color
          rgba="0.792156862745098 0.819607843137255 0.933333333333333 1" />
      </material>
    </visual>
    <collision>
      <origin
        xyz="0 0 0"
        rpy="0 0 0" />
      <geometry>
        <mesh
          filename="package://descripe/meshes/12.STL" />
      </geometry>
    </collision>
  </link>
  <joint
    name="12"
    type="revolute">
    <origin
      xyz="0.0800000000000001 0 -0.014"
      rpy="0 0 -2.14225469636022" />
    <parent
      link="1" />
    <child
      link="12" />
    <axis
      xyz="0 0 1" />
    <limit
      lower="0"
      upper="6.28"
      effort="1000"
      velocity="1000" />
  </joint>
  <link
    name="121">
    <inertial>
      <origin
        xyz="-2.92821322744885E-15 5.55111512312578E-16 0.00407409549700097"
        rpy="0 0 0" />
      <mass
        value="0.000539506193520435" />
      <inertia
        ixx="1.25867201372513E-08"
        ixy="-3.10192729707385E-25"
        ixz="-5.4335426487077E-23"
        iyy="1.25867201372513E-08"
        iyz="-1.08877648127292E-22"
        izz="3.31683628481004E-09" />
    </inertial>
    <visual>
      <origin
        xyz="0 0 0"
        rpy="0 0 0" />
      <geometry>
        <mesh
          filename="package://descripe/meshes/121.STL" />
      </geometry>
      <material
        name="">
        <color
          rgba="0.505882352941176 0.505882352941176 0.584313725490196 1" />
      </material>
    </visual>
    <collision>
      <origin
        xyz="0 0 0"
        rpy="0 0 0" />
      <geometry>
        <mesh
          filename="package://descripe/meshes/121.STL" />
      </geometry>
    </collision>
  </link>
  <joint
    name="121"
    type="revolute">
    <origin
      xyz="0.394850000000003 0 0"
      rpy="0 0 0" />
    <parent
      link="12" />
    <child
      link="121" />
    <axis
      xyz="0 0 1" />
    <limit
      lower="0"
      upper="6.28"
      effort="1000"
      velocity="1000" />
  </joint>
  <link
    name="2">
    <inertial>
      <origin
        xyz="0.0361016048824097 -3.81998845611076E-08 -2.16627963067761E-08"
        rpy="0 0 0" />
      <mass
        value="0.017511882705247" />
      <inertia
        ixx="7.21182417832101E-07"
        ixy="-3.05683665426289E-11"
        ixz="-1.54396755563605E-11"
        iyy="1.08038679441715E-05"
        iyz="-4.42594051820329E-12"
        izz="1.12029329427599E-05" />
    </inertial>
    <visual>
      <origin
        xyz="0 0 0"
        rpy="0 0 0" />
      <geometry>
        <mesh
          filename="package://descripe/meshes/2.STL" />
      </geometry>
      <material
        name="">
        <color
          rgba="0.792156862745098 0.819607843137255 0.933333333333333 1" />
      </material>
    </visual>
    <collision>
      <origin
        xyz="0 0 0"
        rpy="0 0 0" />
      <geometry>
        <mesh
          filename="package://descripe/meshes/2.STL" />
      </geometry>
    </collision>
  </link>
  <joint
    name="2"
    type="revolute">
    <origin
      xyz="-0.065 -0.11258 -0.02"
      rpy="1.5708 -0.08134 -2.0944" />
    <parent
      link="base_link" />
    <child
      link="2" />
    <axis
      xyz="0 0 -1" />
    <limit
      lower="0"
      upper="6.28"
      effort="1000"
      velocity="1000" />
  </joint>
  <link
    name="21">
    <inertial>
      <origin
        xyz="0.197425007172998 7.93569963735349E-05 7.06996290023021E-05"
        rpy="0 0 0" />
      <mass
        value="0.00971847016176818" />
      <inertia
        ixx="5.27630470383877E-08"
        ixy="-1.59042470481183E-14"
        ixz="2.20147016262096E-14"
        iyy="8.64542546902223E-05"
        iyz="1.74497344875077E-09"
        izz="8.64538506463955E-05" />
    </inertial>
    <visual>
      <origin
        xyz="0 0 0"
        rpy="0 0 0" />
      <geometry>
        <mesh
          filename="package://descripe/meshes/21.STL" />
      </geometry>
      <material
        name="">
        <color
          rgba="0.792156862745098 0.819607843137255 0.933333333333333 1" />
      </material>
    </visual>
    <collision>
      <origin
        xyz="0 0 0"
        rpy="0 0 0" />
      <geometry>
        <mesh
          filename="package://descripe/meshes/21.STL" />
      </geometry>
    </collision>
  </link>
  <joint
    name="21"
    type="revolute">
    <origin
      xyz="0.0800000000000006 0 0.0140000000000007"
      rpy="0 0 -2.14225469636022" />
    <parent
      link="2" />
    <child
      link="21" />
    <axis
      xyz="0 0 -1" />
    <limit
      lower="0"
      upper="6.28"
      effort="1000"
      velocity="1000" />
  </joint>
  <link
    name="211">
    <inertial>
      <origin
        xyz="-2.77555756156289E-15 2.28983498828939E-16 -0.00407409549700025"
        rpy="0 0 0" />
      <mass
        value="0.000539506193520435" />
      <inertia
        ixx="1.25867201372514E-08"
        ixy="0"
        ixz="-4.34470654252548E-24"
        iyy="1.25867201372514E-08"
        iyz="-3.59090668585845E-23"
        izz="3.31683628481004E-09" />
    </inertial>
    <visual>
      <origin
        xyz="0 0 0"
        rpy="0 0 0" />
      <geometry>
        <mesh
          filename="package://descripe/meshes/211.STL" />
      </geometry>
      <material
        name="">
        <color
          rgba="0.505882352941176 0.505882352941176 0.584313725490196 1" />
      </material>
    </visual>
    <collision>
      <origin
        xyz="0 0 0"
        rpy="0 0 0" />
      <geometry>
        <mesh
          filename="package://descripe/meshes/211.STL" />
      </geometry>
    </collision>
  </link>
  <joint
    name="211"
    type="revolute">
    <origin
      xyz="0.394850000000002 0 0"
      rpy="0 0 0" />
    <parent
      link="21" />
    <child
      link="211" />
    <axis
      xyz="0 0 -1" />
    <limit
      lower="0"
      upper="6.28"
      effort="1000"
      velocity="1000" />
  </joint>
  <link
    name="22">
    <inertial>
      <origin
        xyz="0.197424998741305 -1.93778028245578E-05 -0.000104501331502069"
        rpy="0 0 0" />
      <mass
        value="0.00971846772863301" />
      <inertia
        ixx="5.27630409314115E-08"
        ixy="-9.65629911330809E-15"
        ixz="1.93074673532759E-15"
        iyy="8.64524127133427E-05"
        iyz="6.2980780077915E-10"
        izz="8.64556923930788E-05" />
    </inertial>
    <visual>
      <origin
        xyz="0 0 0"
        rpy="0 0 0" />
      <geometry>
        <mesh
          filename="package://descripe/meshes/22.STL" />
      </geometry>
      <material
        name="">
        <color
          rgba="0.792156862745098 0.819607843137255 0.933333333333333 1" />
      </material>
    </visual>
    <collision>
      <origin
        xyz="0 0 0"
        rpy="0 0 0" />
      <geometry>
        <mesh
          filename="package://descripe/meshes/22.STL" />
      </geometry>
    </collision>
  </link>
  <joint
    name="22"
    type="revolute">
    <origin
      xyz="0.0800000000000006 0 -0.0139999999999993"
      rpy="0 0 -2.14225469636021" />
    <parent
      link="2" />
    <child
      link="22" />
    <axis
      xyz="0 0 1" />
    <limit
      lower="0"
      upper="6.28"
      effort="1000"
      velocity="1000" />
  </joint>
  <link
    name="221">
    <inertial>
      <origin
        xyz="-2.55351295663786E-15 1.66533453693773E-16 0.004074095497001"
        rpy="0 0 0" />
      <mass
        value="0.000539506193520435" />
      <inertia
        ixx="1.25867201372513E-08"
        ixy="0"
        ixz="-1.78596828051784E-24"
        iyy="1.25867201372513E-08"
        iyz="-3.967356130808E-23"
        izz="3.31683628481004E-09" />
    </inertial>
    <visual>
      <origin
        xyz="0 0 0"
        rpy="0 0 0" />
      <geometry>
        <mesh
          filename="package://descripe/meshes/221.STL" />
      </geometry>
      <material
        name="">
        <color
          rgba="0.505882352941176 0.505882352941176 0.584313725490196 1" />
      </material>
    </visual>
    <collision>
      <origin
        xyz="0 0 0"
        rpy="0 0 0" />
      <geometry>
        <mesh
          filename="package://descripe/meshes/221.STL" />
      </geometry>
    </collision>
  </link>
  <joint
    name="221"
    type="revolute">
    <origin
      xyz="0.394850000000001 0 0"
      rpy="0 0 0" />
    <parent
      link="22" />
    <child
      link="221" />
    <axis
      xyz="0 0 1" />
    <limit
      lower="0"
      upper="6.28"
      effort="1000"
      velocity="1000" />
  </joint>
  <link
    name="3">
    <inertial>
      <origin
        xyz="0.0361016048824093 -3.91730035353977E-08 -1.98490237302007E-08"
        rpy="0 0 0" />
      <mass
        value="0.017511882705247" />
      <inertia
        ixx="7.21182417832099E-07"
        ixy="-3.12582639118428E-11"
        ixz="-1.39903378111715E-11"
        iyy="1.0804743752541E-05"
        iyz="1.86745132475821E-08"
        izz="1.12020571343904E-05" />
    </inertial>
    <visual>
      <origin
        xyz="0 0 0"
        rpy="0 0 0" />
      <geometry>
        <mesh
          filename="package://descripe/meshes/3.STL" />
      </geometry>
      <material
        name="">
        <color
          rgba="0.792156862745098 0.819607843137255 0.933333333333333 1" />
      </material>
    </visual>
    <collision>
      <origin
        xyz="0 0 0"
        rpy="0 0 0" />
      <geometry>
        <mesh
          filename="package://descripe/meshes/3.STL" />
      </geometry>
    </collision>
  </link>
  <joint
    name="3"
    type="revolute">
    <origin
      xyz="-0.065 0.11258 -0.02"
      rpy="1.6177 -0.08134 2.0944" />
    <parent
      link="base_link" />
    <child
      link="3" />
    <axis
      xyz="0 -0.046858 -0.9989" />
    <limit
      lower="0"
      upper="6.28"
      effort="1000"
      velocity="1000" />
  </joint>
  <link
    name="31">
    <inertial>
      <origin
        xyz="0.197425016831845 4.9557640513731E-05 9.40214578554061E-05"
        rpy="0 0 0" />
      <mass
        value="0.00971846919620296" />
      <inertia
        ixx="5.27630377715992E-08"
        ixy="-4.33566700471402E-14"
        ixz="2.8307333567339E-14"
        iyy="8.64530598532524E-05"
        iyz="1.4491796074449E-09"
        izz="8.64550454084133E-05" />
    </inertial>
    <visual>
      <origin
        xyz="0 0 0"
        rpy="0 0 0" />
      <geometry>
        <mesh
          filename="package://descripe/meshes/31.STL" />
      </geometry>
      <material
        name="">
        <color
          rgba="0.792156862745098 0.819607843137255 0.933333333333333 1" />
      </material>
    </visual>
    <collision>
      <origin
        xyz="0 0 0"
        rpy="0 0 0" />
      <geometry>
        <mesh
          filename="package://descripe/meshes/31.STL" />
      </geometry>
    </collision>
  </link>
  <joint
    name="31"
    type="revolute">
    <origin
      xyz="0.0799999999999981 0.00065601454101416 0.0139846217296698"
      rpy="0.0253661095847956 -0.0394232412580098 -2.14275479506331" />
    <parent
      link="3" />
    <child
      link="31" />
    <axis
      xyz="0 0 -1" />
    <limit
      lower="0"
      upper="6.28"
      effort="1000"
      velocity="1000" />
  </joint>
  <link
    name="311">
    <inertial>
      <origin
        xyz="2.77555756156289E-17 6.38378239159465E-16 -0.00407409549700054"
        rpy="0 0 0" />
      <mass
        value="0.000539506193520435" />
      <inertia
        ixx="1.25867201372513E-08"
        ixy="2.06795153138257E-25"
        ixz="-5.06648125188729E-24"
        iyy="1.25867201372513E-08"
        iyz="-2.67799723314043E-23"
        izz="3.31683628481005E-09" />
    </inertial>
    <visual>
      <origin
        xyz="0 0 0"
        rpy="0 0 0" />
      <geometry>
        <mesh
          filename="package://descripe/meshes/311.STL" />
      </geometry>
      <material
        name="">
        <color
          rgba="0.505882352941176 0.505882352941176 0.584313725490196 1" />
      </material>
    </visual>
    <collision>
      <origin
        xyz="0 0 0"
        rpy="0 0 0" />
      <geometry>
        <mesh
          filename="package://descripe/meshes/311.STL" />
      </geometry>
    </collision>
  </link>
  <joint
    name="311"
    type="revolute">
    <origin
      xyz="0.394849999999999 0 0"
      rpy="0 0 0" />
    <parent
      link="31" />
    <child
      link="311" />
    <axis
      xyz="0 0 -1" />
    <limit
      lower="0"
      upper="6.28"
      effort="1000"
      velocity="1000" />
  </joint>
  <link
    name="32">
    <inertial>
      <origin
        xyz="0.19742498319943 -4.95577731194907E-05 -9.40213842750698E-05"
        rpy="0 0 0" />
      <mass
        value="0.00971846911141238" />
      <inertia
        ixx="5.27630336772175E-08"
        ixy="-2.03796394632002E-14"
        ixz="1.61252797671359E-14"
        iyy="8.64530598526678E-05"
        iyz="1.44917885692628E-09"
        izz="8.64550453997248E-05" />
    </inertial>
    <visual>
      <origin
        xyz="0 0 0"
        rpy="0 0 0" />
      <geometry>
        <mesh
          filename="package://descripe/meshes/32.STL" />
      </geometry>
      <material
        name="">
        <color
          rgba="0.792156862745098 0.819607843137255 0.933333333333333 1" />
      </material>
    </visual>
    <collision>
      <origin
        xyz="0 0 0"
        rpy="0 0 0" />
      <geometry>
        <mesh
          filename="package://descripe/meshes/32.STL" />
      </geometry>
    </collision>
  </link>
  <joint
    name="32"
    type="revolute">
    <origin
      xyz="0.0799999999999981 -0.000656014541008387 -0.013984621729672"
      rpy="0.0253661095847951 -0.0394232412580078 -2.14275479506331" />
    <parent
      link="3" />
    <child
      link="32" />
    <axis
      xyz="0 0 1" />
    <limit
      lower="0"
      upper="6.28"
      effort="1000"
      velocity="1000" />
  </joint>
  <link
    name="321">
    <inertial>
      <origin
        xyz="-5.89805981832114E-17 6.66133814775094E-16 0.0040740954970007"
        rpy="0 0 0" />
      <mass
        value="0.000539506193520436" />
      <inertia
        ixx="1.25867201372514E-08"
        ixy="3.10192729707385E-25"
        ixz="5.89366186444032E-24"
        iyy="1.25867201372514E-08"
        iyz="-2.12999007732405E-23"
        izz="3.31683628481004E-09" />
    </inertial>
    <visual>
      <origin
        xyz="0 0 0"
        rpy="0 0 0" />
      <geometry>
        <mesh
          filename="package://descripe/meshes/321.STL" />
      </geometry>
      <material
        name="">
        <color
          rgba="0.505882352941176 0.505882352941176 0.584313725490196 1" />
      </material>
    </visual>
    <collision>
      <origin
        xyz="0 0 0"
        rpy="0 0 0" />
      <geometry>
        <mesh
          filename="package://descripe/meshes/321.STL" />
      </geometry>
    </collision>
  </link>
  <joint
    name="321"
    type="revolute">
    <origin
      xyz="0.394849999999999 0 0"
      rpy="0 0 0" />
    <parent
      link="32" />
    <child
      link="321" />
    <axis
      xyz="0 0 1" />
    <limit
      lower="0"
      upper="6.28"
      effort="1000"
      velocity="1000" />
  </joint>
  <link
    name="4">
    <inertial>
      <origin
        xyz="4.22051041337745E-09 7.90242890569282E-09 0.00644065846947697"
        rpy="0 0 0" />
      <mass
        value="0.00151305684520863" />
      <inertia
        ixx="7.76380429873237E-08"
        ixy="1.06758944474477E-13"
        ixz="-1.27965978349675E-13"
        iyy="6.42955272093896E-08"
        iyz="2.85021212069954E-13"
        izz="5.48378642213392E-08" />
    </inertial>
    <visual>
      <origin
        xyz="0 0 0"
        rpy="0 0 0" />
      <geometry>
        <mesh
          filename="package://descripe/meshes/4.STL" />
      </geometry>
      <material
        name="">
        <color
          rgba="0.756862745098039 0.768627450980392 0.752941176470588 1" />
      </material>
    </visual>
    <collision>
      <origin
        xyz="0 0 0"
        rpy="0 0 0" />
      <geometry>
        <mesh
          filename="package://descripe/meshes/4.STL" />
      </geometry>
    </collision>
  </link>
  <joint
    name="4"
    type="revolute">
    <origin
      xyz="0 0 -0.0200000000000002"
      rpy="0 0 0.0374025114052824" />
    <parent
      link="base_link" />
    <child
      link="4" />
    <axis
      xyz="0 0 1" />
    <limit
      lower="0"
      upper="6.28"
      effort="1000"
      velocity="1000" />
  </joint>
  <link
    name="41">
    <inertial>
      <origin
        xyz="-1.36002320516582E-15 -1.94289029309402E-16 -2.77555756156289E-17"
        rpy="0 0 0" />
      <mass
        value="0.000852115950566532" />
      <inertia
        ixx="1.2127907628535E-08"
        ixy="1.51636995168832E-23"
        ixz="-4.13590306276514E-25"
        iyy="1.48133687782392E-08"
        iyz="2.10508903819108E-24"
        izz="1.2127907628535E-08" />
    </inertial>
    <visual>
      <origin
        xyz="0 0 0"
        rpy="0 0 0" />
      <geometry>
        <mesh
          filename="package://descripe/meshes/41.STL" />
      </geometry>
      <material
        name="">
        <color
          rgba="0.756862745098039 0.768627450980392 0.752941176470588 1" />
      </material>
    </visual>
    <collision>
      <origin
        xyz="0 0 0"
        rpy="0 0 0" />
      <geometry>
        <mesh
          filename="package://descripe/meshes/41.STL" />
      </geometry>
    </collision>
  </link>
  <joint
    name="41"
    type="revolute">
    <origin
      xyz="0 0 -0.00399999999999989"
      rpy="1.5707963267949 0 0" />
    <parent
      link="4" />
    <child
      link="41" />
    <axis
      xyz="0 0 -1" />
    <limit
      lower="0"
      upper="6.28"
      effort="1000"
      velocity="1000" />
  </joint>
  <link
    name="411">
    <inertial>
      <origin
        xyz="-0.113275443707768 -4.3362397006419E-10 7.89386500610334E-10"
        rpy="0 0 0" />
      <mass
        value="0.0151504453724169" />
      <inertia
        ixx="6.41413678015845E-07"
        ixy="-1.26739956930487E-13"
        ixz="-2.84889742136951E-13"
        iyy="3.92328614975377E-05"
        iyz="-1.06798338889939E-13"
        izz="3.95821990660992E-05" />
    </inertial>
    <visual>
      <origin
        xyz="0 0 0"
        rpy="0 0 0" />
      <geometry>
        <mesh
          filename="package://descripe/meshes/411.STL" />
      </geometry>
      <material
        name="">
        <color
          rgba="0.756862745098039 0.768627450980392 0.752941176470588 1" />
      </material>
    </visual>
    <collision>
      <origin
        xyz="0 0 0"
        rpy="0 0 0" />
      <geometry>
        <mesh
          filename="package://descripe/meshes/411.STL" />
      </geometry>
    </collision>
  </link>
  <joint
    name="411"
    type="revolute">
    <origin
      xyz="0 0 0"
      rpy="1.5707963267949 0 1.57079632679489" />
    <parent
      link="41" />
    <child
      link="411" />
    <axis
      xyz="0 0 -1" />
    <limit
      lower="0"
      upper="6.28"
      effort="1000"
      velocity="1000" />
  </joint>
  <link
    name="4111">
    <inertial>
      <origin
        xyz="-7.99613625313E-10 -1.49719046882435E-09 0.120044998050398"
        rpy="0 0 0" />
      <mass
        value="0.00798617591742343" />
      <inertia
        ixx="1.96486123039808E-05"
        ixy="1.06758945081628E-13"
        ixz="1.27966215744159E-13"
        iyy="1.9806006955144E-05"
        iyz="-2.85021194990854E-13"
        izz="3.33730404518576E-07" />
    </inertial>
    <visual>
      <origin
        xyz="0 0 0"
        rpy="0 0 0" />
      <geometry>
        <mesh
          filename="package://descripe/meshes/4111.STL" />
      </geometry>
      <material
        name="">
        <color
          rgba="0.792156862745098 0.819607843137255 0.933333333333333 1" />
      </material>
    </visual>
    <collision>
      <origin
        xyz="0 0 0"
        rpy="0 0 0" />
      <geometry>
        <mesh
          filename="package://descripe/meshes/4111.STL" />
      </geometry>
    </collision>
  </link>
  <joint
    name="4111"
    type="prismatic">
    <origin
      xyz="-0.311867067884886 0 0"
      rpy="1.5707963267949 0 1.57079632679491" />
    <parent
      link="411" />
    <child
      link="4111" />
    <axis
      xyz="0 0 1" />
    <limit
      lower="0"
      upper="6.28"
      effort="1000"
      velocity="1000" />
  </joint>
  <link
    name="41111">
    <inertial>
      <origin
        xyz="8.32667268468867E-17 6.93889390390723E-17 3.05311331771918E-16"
        rpy="0 0 0" />
      <mass
        value="0.000852115950566531" />
      <inertia
        ixx="1.2127907628535E-08"
        ixy="-5.7725988742426E-24"
        ixz="-2.48154183765908E-24"
        iyy="1.48133687782392E-08"
        iyz="-1.75584902064304E-23"
        izz="1.2127907628535E-08" />
    </inertial>
    <visual>
      <origin
        xyz="0 0 0"
        rpy="0 0 0" />
      <geometry>
        <mesh
          filename="package://descripe/meshes/41111.STL" />
      </geometry>
      <material
        name="">
        <color
          rgba="0.756862745098039 0.768627450980392 0.752941176470588 1" />
      </material>
    </visual>
    <collision>
      <origin
        xyz="0 0 0"
        rpy="0 0 0" />
      <geometry>
        <mesh
          filename="package://descripe/meshes/41111.STL" />
      </geometry>
    </collision>
  </link>
  <joint
    name="41111"
    type="revolute">
    <origin
      xyz="0 0 0"
      rpy="1.5707963267949 0 0" />
    <parent
      link="4111" />
    <child
      link="41111" />
    <axis
      xyz="0 0 -1" />
    <limit
      lower="0"
      upper="6.28"
      effort="1000"
      velocity="1000" />
  </joint>
  <link
    name="411111">
    <inertial>
      <origin
        xyz="-0.0258618985042972 -8.44322264881292E-10 1.53939538893866E-09"
        rpy="0 0 0" />
      <mass
        value="0.00777029234237776" />
      <inertia
        ixx="5.68324834833635E-07"
        ixy="-1.26739956260412E-13"
        ixz="-2.84889744292174E-13"
        iyy="5.93752025348481E-07"
        iyz="-1.06798541145525E-13"
        izz="5.80409509616738E-07" />
    </inertial>
    <visual>
      <origin
        xyz="0 0 0"
        rpy="0 0 0" />
      <geometry>
        <mesh
          filename="package://descripe/meshes/411111.STL" />
      </geometry>
      <material
        name="">
        <color
          rgba="0.756862745098039 0.768627450980392 0.752941176470588 1" />
      </material>
    </visual>
    <collision>
      <origin
        xyz="0 0 0"
        rpy="0 0 0" />
      <geometry>
        <mesh
          filename="package://descripe/meshes/411111.STL" />
      </geometry>
    </collision>
  </link>
  <joint
    name="411111"
    type="revolute">
    <origin
      xyz="0 0 0"
      rpy="1.5708 0 1.5708" />
    <parent
      link="41111" />
    <child
      link="411111" />
    <axis
      xyz="0 0 1" />
    <limit
      lower="0"
      upper="6.28"
      effort="1000"
      velocity="1000" />
  </joint>
</robot>